Workbook
Name Cg: 0.00008846
Name clight: 299792458
Name Cq: 0.00000000000038319
Name echarge: 1.602176634E-19
Name emass: 0.000510998949996164
Name table_quad: V26_LCC_dipoles!#REF!
Name table_quad: V26_LCC_quadrupoles!#REF!

Sheet V26_LCC
A1: Keyword | B1: Parameter | C1: Unit | D1: Z | E1: W | F1: ZH | G1: ttbar | H1: Comments
B2: Layout
A3: LAYOUT | B3: Version | D3: V160.2
A4: NUMBER_IPS | B4: Number of Ips | D4: 4
A5: CIRCUMFERENCE | B5: Circumference | C5: km | D5: 90.644836
A6: REVOLUTION_PERIOD | B6: Revolution period | C6: ms | D6: =D5*1000/clight*1000 -> 0.30235863
A7: OFFSET_IP | B7: Offset IP | C7: m | D7: -20.228963
A8: HORIZONTAL_ARC_OFFSET | B8: Hor. Arc offset booster-collider | C8: m | D8: 0.5585
B9: General parameters
A10: INJECTOR | B10: Injector | D10: LINAC
A11: NUMBER_CYCLINGS_FILLING_COLLIDER | B11: Number of booster cyclings to have a full collider ramp | D11: 10 | E11: 2 | F11: 1 | G11: 1
A12: NUMBER_BUNCHES_COLLIDER | B12: Number bunches/collider | D12: 11200 | E12: 1852 | F12: 300 | G12: 64
A13: NUMBER_BUNCHES | B13: Number bunches/booster | D13: =D12/D11 -> 1120 | E13: =E12/E11 -> 926 | F13: =F12/F11 -> 300 | G13: =G12/G11 -> 64
A14: BUNCH_POPULATION_COLLIDER | B14: Collider particles/bunch | C14: 10000000000 | D14: 21.6 | E14: 13.8 | F14: 16.9 | G14: 14.8
A15: ALLOWED_CHARGE_BALANCE_COLLIDER | B15: Allowable charge balance | C15: % | D15: 5 | E15: 3 | F15: 3 | G15: 3
A16: BUNCH_POPULATION_FILLING | B16: Particle number / bunch (filling) | C16: 10000000000 | D16: 2.5 | E16: 2.5 | F16: 1 | G16: 1
A17: BUNCH_CHARGE_FILLING | B17: Bunch charge (filling) | C17: nC | D17: =D16*10000000000000000000*echarge -> 4.0054416 | E17: =E16*10000000000000000000*echarge -> 4.0054416 | F17: =F16*10000000000000000000*echarge -> 1.6021766 | G17: =G16*10000000000000000000*echarge -> 1.6021766
A18: BEAM_CURRENT_FILLING | B18: Mean beam current (filling) | C18: mA | D18: =D17*D13/$D$6/1000 -> 14.836999 | E18: =E17*E13/$D$6/1000 -> 12.267019 | F18: =F17*F13/$D$6/1000 -> 1.5896784 | G18: =G17*G13/$D$6/1000 -> 0.3391314
A19: BUNCH_POPULATION_TOPUP | B19: Maximum bootstrap particle number / bunch (top-up) | C19: 10000000000 | D19: =2*D15/100*D14 -> 2.16 | E19: =2*E15/100*E14 -> 0.828 | F19: =2*F15/100*F14 -> 1.014 | G19: =2*G15/100*G14 -> 0.888
A20: BUNCH_CHARGE_TOPUP | B20: Maximum bootstrap bunch charge (top-up) | C20: nC | D20: =D19*10000000000000000000*echarge -> 3.4607015 | E20: =E19*10000000000000000000*echarge -> 1.3266023 | F20: =F19*10000000000000000000*echarge -> 1.6246071 | G20: =G19*10000000000000000000*echarge -> 1.4227329
A21: BEAM_CURRENT_TOPUP | B21: Mean beam current (top-up) | C21: mA | D21: =D20*D13/$D$6/1000 -> 12.819167 | E21: =E20*E13/$D$6/1000 -> 4.0628366 | F21: =F20*F13/$D$6/1000 -> 1.6119339 | G21: =G20*G13/$D$6/1000 -> 0.30114868
A22: LIFETIME_COLLIDER | B22: Collider beam life time at collisions | C22: s | D22: 868.1 | E22: 492.4 | F22: 376.2 | G22: 348.2
A23: INJECTION_INTERVAL_TOPUP | B23: Collider top-up interval (between e+ and e-) | C23: s | D23: =D22*D15/100 -> 43.405 | E23: =E22*E15/100 -> 14.772 | F23: =F22*F15/100 -> 11.286 | G23: =G22*G15/100 -> 10.446
B24: Injection Beam parameters
A25: ENERGY_INJECTION | B25: Injection energy | C25: GeV | D25: 20 | E25: 20 | F25: 20 | G25: 20
A26: BRHO_INJECTION | B26: Injection magnetic rigidity | C26: Tm | D26: =D25*1000000000/clight -> 66.712819 | E26: =E25*1000000000/clight -> 66.712819 | F26: =F25*1000000000/clight -> 66.712819 | G26: =G25*1000000000/clight -> 66.712819
A27: GAMMA_INJECTION | B27: Injection gamma | D27: =D25/emass -> 39139.024 | E27: =E25/emass -> 39139.024 | F27: =F25/emass -> 39139.024 | G27: =G25/emass -> 39139.024
A28: BEAM_ENERGY_EXTRACTION | B28: Injection beam energy | C28: kJ | D28: =D25*D13*D17/1000 -> 89.721892 | E28: =E25*E13*E17/1000 -> 74.180778 | F28: =F25*F13*F17/1000 -> 9.6130598 | G28: =G25*G13*G17/1000 -> 2.0507861
A29: NORM_EMITTANCE_X_INJECTION | B29: Injection horizontal emittance (norm.) | C29: µm | D29: 20 | E29: 20 | F29: 20 | G29: 20 | H29: To be validated
A30: NORM_EMITTANCE_Y_INJECTION | B30: Injection vertical emittance (norm.) | C30: µm | D30: 2 | E30: 2 | F30: 2 | G30: 2 | H30: To be validated
A31: BUNCH_LENGTH_INJECTION | B31: Injection RMS bunch length | C31: mm | D31: 4 | E31: 4 | F31: 4 | G31: 4 | H31: To be validated
A32: ENERGY_SPREAD_INJECTION | B32: Injection RMS energy spread | D32: 0.001 | E32: 0.001 | F32: 0.001 | G32: 0.001 | H32: To be validated
B33: Extraction Beam parameters
A34: ENERGY_EXTRACTION | B34: Extraction energy | C34: GeV | D34: 45.6 | E34: 80 | F34: 120 | G34: 182.5
A35: BRHO_EXTRACTION | B35: Extraction magnetic rigidity | C35: Tm | D35: =D34*1000000000/clight -> 152.10523 | E35: =E34*1000000000/clight -> 266.85128 | F35: =F34*1000000000/clight -> 400.27691 | G35: =G34*1000000000/clight -> 608.75447
A36: GAMMA_EXTRACTION | B36: Extraction gamma | D36: =D34/emass -> 89236.974 | E36: =E34/emass -> 156556.09 | F36: =F34/emass -> 234834.14 | G36: =G34/emass -> 357143.59
A37: BEAM_ENERGY_EXTRACTION | B37: Extraction beam energy | C37: kJ | D37: =D34*D13*D17/1000 -> 204.56591 | E37: =E34*E13*E17/1000 -> 296.72311 | F37: =F34*F13*F17/1000 -> 57.678359 | G37: =G34*G13*G17/1000 -> 18.713423
A38: NORM_EMITTANCE_X_EXTRACTION | B38: Extraction horizontal emittance (RMS) | C38: nm | D38: 0.122 | E38: =E59 -> 0.36698033 | F38: =F59 -> 0.82570575 | G38: =G59 -> 1.9098029 | H38: To be updated according to ramp
A39: NORM_EMITTANCE_Y_EXTRACTION | B39: Extraction vertical emittance (RMS) | C39: pm | D39: 37 | E39: =E60 -> 0.73396066 | F39: =F60 -> 1.6514115 | G39: =G60 -> 3.8196058 | H39: To be updated according to ramp
A40: BUNCH_LENGTH_EXTRACTION | B40: Extraction bunch length | C40: mm | D40: =(2*PI()*(1/D36^2-D$50)/$D$65/D77*$D$5*1/COS(D75*PI()/180)*D34)^0.5*D43*1000000*$D$65/2/PI() -> 2.6151797 | E40: =E61 -> 2.7556109 | F40: =F61 -> 2.4422381 | G40: =G61 -> 2.1397339 | H40: To be updated according to ramp
...

Sheet V26_LCC_dipoles
A1: Length | B1: Angle [rad] | C1: Norm strength [m-1] | D1: Number | E1: Field injection [T] | F1: Field at Z [T] | J1: Length Min
A2: 9.4 | B2: 0.00087130732 | C2: 9.2692268e-05 | D2: 7104 | E2: =ABS($B2/$A2*V26_LCC!D$26) -> 0.0061837625 | F2: =ABS($B2/$A2*V26_LCC!D$35) -> 0.014098979 | G2: =ABS($B2/$A2*V26_LCC!E$35) -> 0.02473505 | H2: =ABS($B2/$A2*V26_LCC!F$35) -> 0.037102575 | I2: =ABS($B2/$A2*V26_LCC!G$35) -> 0.056426833 | J2: =I2/V26_LCC!$D$114*A2 -> 0.017238398
A3: 9.4000146 | B3: 0.00087130868 | C3: 9.2692268e-05 | D3: 48 | E3: =ABS($B3/$A3*V26_LCC!D$26) -> 0.0061837625 | F3: =ABS($B3/$A3*V26_LCC!D$35) -> 0.014098979 | G3: =ABS($B3/$A3*V26_LCC!E$35) -> 0.02473505 | H3: =ABS($B3/$A3*V26_LCC!F$35) -> 0.037102575 | I3: =ABS($B3/$A3*V26_LCC!G$35) -> 0.056426833 | J3: =I3/V26_LCC!$D$114*A3 -> 0.017238424 | L3: Total number of magnets | M3: =SUM(D2:D33) -> 7200
A4: 11.596452 | B4: 0.0010749014 | C4: 9.2692268e-05 | D4: 48 | E4: =ABS($B4/$A4*V26_LCC!D$26) -> 0.0061837625 | F4: =ABS($B4/$A4*V26_LCC!D$35) -> 0.014098979 | G4: =ABS($B4/$A4*V26_LCC!E$35) -> 0.02473505 | H4: =ABS($B4/$A4*V26_LCC!F$35) -> 0.037102575 | I4: =ABS($B4/$A4*V26_LCC!G$35) -> 0.056426833 | J4: =I4/V26_LCC!$D$114*A4 -> 0.021266409 | L4: Total length | M4: =SUMPRODUCT(A2:A33,D2:D33) -> 67785.43
L5: Total normalized gradient | M5: {=SUMPRODUCT((B2:B33)*(D2:D33)*SIGN(B2:B33))} -> 6.2831853
L11: MIN | M11: Min field (injection) T | P11: =MIN(E1:E69) -> 0.0061837625 | Q11: =MIN(F1:F69) -> 0.014098979 | R11: =MIN(G1:G69) -> 0.02473505 | S11: =MIN(H1:H69) -> 0.037102575 | T11: =MIN(I1:I69) -> 0.056426833
L12: MAX | M12: Max field (injection) T | P12: =MAX(E2:E69) -> 0.0061837625 | Q12: =MAX(F2:F69) -> 0.014098979 | R12: =MAX(G2:G69) -> 0.02473505 | S12: =MAX(H2:H69) -> 0.037102575 | T12: =MAX(I2:I69) -> 0.056426833
L13: MEAN | M13: Mean field (injection) T | P13: =SUMPRODUCT($D$2:$D$69,E2:E69)/$M$3 -> 0.0061837625 | Q13: =SUMPRODUCT($D$2:$D$69,F2:F69)/$M$3 -> 0.014098979 | R13: =SUMPRODUCT($D$2:$D$69,G2:G69)/$M$3 -> 0.02473505 | S13: =SUMPRODUCT($D$2:$D$69,H2:H69)/$M$3 -> 0.037102575 | T13: =SUMPRODUCT($D$2:$D$69,I2:I69)/$M$3 -> 0.056426833

Sheet V26_LCC_quadrupoles
A1: Length | B1: Integrated strength | C1: Norm strength [m-2] | D1: Number | E1: Gradient injection [T/m] | F1: Gradient at Z [T/m] | J1: Length Min
A2: 1.6 | B2: -0.042776431 | C2: -0.026735269 | D2: 8 | E2: =ABS($B2/$A2*V26_LCC!D$26) -> 1.7835852 | F2: =ABS($B2/$A2*V26_LCC!D$35) -> 4.0665742 | G2: =ABS($B2/$A2*V26_LCC!E$35) -> 7.1343408 | H2: =ABS($B2/$A2*V26_LCC!F$35) -> 10.701511 | I2: =ABS($B2/$A2*V26_LCC!G$35) -> 16.275215 | J2: =I2/V26_LCC!$D$114*A2 -> 0.84631117
A3: 1.6 | B3: -0.038063408 | C3: -0.02378963 | D3: 8 | E3: =ABS($B3/$A3*V26_LCC!D$26) -> 1.5870733 | F3: =ABS($B3/$A3*V26_LCC!D$35) -> 3.6185271 | G3: =ABS($B3/$A3*V26_LCC!E$35) -> 6.3482931 | H3: =ABS($B3/$A3*V26_LCC!F$35) -> 9.5224396 | I3: =ABS($B3/$A3*V26_LCC!G$35) -> 14.482044 | J3: =I3/V26_LCC!$D$114*A3 -> 0.75306627 | L3: Total number of magnets | M3: =SUM(D2:D33) -> 2716
A4: 1.6 | B4: -0.034596056 | C4: -0.021622535 | D4: 8 | E4: =ABS($B4/$A4*V26_LCC!D$26) -> 1.4425003 | F4: =ABS($B4/$A4*V26_LCC!D$35) -> 3.2889006 | G4: =ABS($B4/$A4*V26_LCC!E$35) -> 5.770001 | H4: =ABS($B4/$A4*V26_LCC!F$35) -> 8.6550015 | I4: =ABS($B4/$A4*V26_LCC!G$35) -> 13.162815 | J4: =I4/V26_LCC!$D$114*A4 -> 0.68446637 | L4: Total length | M4: =SUMPRODUCT(A2:A33,D2:D33) -> 6220.08
A5: 1.6 | B5: -0.027517864 | C5: -0.017198665 | D5: 64 | E5: =ABS($B5/$A5*V26_LCC!D$26) -> 1.1473714 | F5: =ABS($B5/$A5*V26_LCC!D$35) -> 2.6160069 | G5: =ABS($B5/$A5*V26_LCC!E$35) -> 4.5894857 | H5: =ABS($B5/$A5*V26_LCC!F$35) -> 6.8842286 | I5: =ABS($B5/$A5*V26_LCC!G$35) -> 10.469764 | J5: =I5/V26_LCC!$D$114*A5 -> 0.54442774 | L5: Total normalized gradient | M5: {=SUMPRODUCT((B2:B33)*(D2:D33)*SIGN(B2:B33))} -> 116.17615
A6: 1.6 | B6: -0.023941665 | C6: -0.014963541 | D6: 8 | E6: =ABS($B6/$A6*V26_LCC!D$26) -> 0.99825998 | F6: =ABS($B6/$A6*V26_LCC!D$35) -> 2.2760328 | G6: =ABS($B6/$A6*V26_LCC!E$35) -> 3.9930399 | H6: =ABS($B6/$A6*V26_LCC!F$35) -> 5.9895599 | I6: =ABS($B6/$A6*V26_LCC!G$35) -> 9.1091223 | J6: =I6/V26_LCC!$D$114*A6 -> 0.47367436
A7: 1.6 | B7: -0.022641336 | C7: -0.014150835 | D7: 32 | E7: =ABS($B7/$A7*V26_LCC!D$26) -> 0.94404211 | F7: =ABS($B7/$A7*V26_LCC!D$35) -> 2.152416 | G7: =ABS($B7/$A7*V26_LCC!E$35) -> 3.7761684 | H7: =ABS($B7/$A7*V26_LCC!F$35) -> 5.6642526 | I7: =ABS($B7/$A7*V26_LCC!G$35) -> 8.6143842 | J7: =I7/V26_LCC!$D$114*A7 -> 0.44794798
A8: 1.6 | B8: -0.021808825 | C8: -0.013630516 | D8: 8 | E8: =ABS($B8/$A8*V26_LCC!D$26) -> 0.90933013 | F8: =ABS($B8/$A8*V26_LCC!D$35) -> 2.0732727 | G8: =ABS($B8/$A8*V26_LCC!E$35) -> 3.6373205 | H8: =ABS($B8/$A8*V26_LCC!F$35) -> 5.4559808 | I8: =ABS($B8/$A8*V26_LCC!G$35) -> 8.2976375 | J8: =I8/V26_LCC!$D$114*A8 -> 0.43147715
A9: 1.6 | B9: -0.02162561 | C9: -0.013516006 | D9: 8 | E9: =ABS($B9/$A9*V26_LCC!D$26) -> 0.9016909 | F9: =ABS($B9/$A9*V26_LCC!D$35) -> 2.0558552 | G9: =ABS($B9/$A9*V26_LCC!E$35) -> 3.6067636 | H9: =ABS($B9/$A9*V26_LCC!F$35) -> 5.4101454 | I9: =ABS($B9/$A9*V26_LCC!G$35) -> 8.2279294 | J9: =I9/V26_LCC!$D$114*A9 -> 0.42785233
A10: 1.6 | B10: -0.016254351 | C10: -0.010158969 | D10: 8 | E10: =ABS($B10/$A10*V26_LCC!D$26) -> 0.67773348 | F10: =ABS($B10/$A10*V26_LCC!D$35) -> 1.5452323 | G10: =ABS($B10/$A10*V26_LCC!E$35) -> 2.7109339 | H10: =ABS($B10/$A10*V26_LCC!F$35) -> 4.0664009 | I10: =ABS($B10/$A10*V26_LCC!G$35) -> 6.184318 | J10: =I10/V26_LCC!$D$114*A10 -> 0.32158454
A11: 1.6 | B11: 0.019507439 | C11: 0.01219215 | D11: 8 | E11: =ABS($B11/$A11*V26_LCC!D$26) -> 0.81337267 | F11: =ABS($B11/$A11*V26_LCC!D$35) -> 1.8544897 | G11: =ABS($B11/$A11*V26_LCC!E$35) -> 3.2534907 | H11: =ABS($B11/$A11*V26_LCC!F$35) -> 4.880236 | I11: =ABS($B11/$A11*V26_LCC!G$35) -> 7.4220257 | J11: =I11/V26_LCC!$D$114*A11 -> 0.38594533 | L11: MIN | M11: Min gradient (injection) T/m | P11: =MIN(E1:E69) -> 0.67773348 | Q11: =MIN(F1:F69) -> 1.5452323 | R11: =MIN(G1:G69) -> 2.7109339 | S11: =MIN(H1:H69) -> 4.0664009 | T11: =MIN(I1:I69) -> 6.184318
A12: 1.6 | B12: 0.024293694 | C12: 0.015183559 | D12: 32 | E12: =ABS($B12/$A12*V26_LCC!D$26) -> 1.012938 | F12: =ABS($B12/$A12*V26_LCC!D$35) -> 2.3094987 | G12: =ABS($B12/$A12*V26_LCC!E$35) -> 4.051752 | H12: =ABS($B12/$A12*V26_LCC!F$35) -> 6.0776281 | I12: =ABS($B12/$A12*V26_LCC!G$35) -> 9.2430594 | J12: =I12/V26_LCC!$D$114*A12 -> 0.48063909 | L12: MAX | M12: Max gradient (injection) T/m | P12: =MAX(E2:E69) -> 2.6952762 | Q12: =MAX(F2:F69) -> 6.1452298 | R12: =MAX(G2:G69) -> 10.781105 | S12: =MAX(H2:H69) -> 16.171657 | T12: =MAX(I2:I69) -> 24.594395
A13: 1.6 | B13: 0.026461836 | C13: 0.016538647 | D13: 8 | E13: =ABS($B13/$A13*V26_LCC!D$26) -> 1.1033398 | F13: =ABS($B13/$A13*V26_LCC!D$35) -> 2.5156147 | G13: =ABS($B13/$A13*V26_LCC!E$35) -> 4.4133592 | H13: =ABS($B13/$A13*V26_LCC!F$35) -> 6.6200387 | I13: =ABS($B13/$A13*V26_LCC!G$35) -> 10.067976 | J13: =I13/V26_LCC!$D$114*A13 -> 0.52353473 | L13: MEAN | M13: Mean gradient (injection) T/m | P13: =SUMPRODUCT($D$2:$D$69,E2:E69)/$M$3 -> 1.3162871 | Q13: =SUMPRODUCT($D$2:$D$69,F2:F69)/$M$3 -> 3.0011346 | R13: =SUMPRODUCT($D$2:$D$69,G2:G69)/$M$3 -> 5.2651484 | S13: =SUMPRODUCT($D$2:$D$69,H2:H69)/$M$3 -> 7.8977225 | T13: =SUMPRODUCT($D$2:$D$69,I2:I69)/$M$3 -> 12.01112
A14: 1.6 | B14: 0.028334363 | C14: 0.017708977 | D14: 68 | E14: =ABS($B14/$A14*V26_LCC!D$26) -> 1.1814158 | F14: =ABS($B14/$A14*V26_LCC!D$35) -> 2.693628 | G14: =ABS($B14/$A14*V26_LCC!E$35) -> 4.7256631 | H14: =ABS($B14/$A14*V26_LCC!F$35) -> 7.0884947 | I14: =ABS($B14/$A14*V26_LCC!G$35) -> 10.780419 | J14: =I14/V26_LCC!$D$114*A14 -> 0.56058179
A15: 1.6 | B15: 0.032982024 | C15: 0.020613765 | D15: 8 | E15: =ABS($B15/$A15*V26_LCC!D$26) -> 1.3752024 | F15: =ABS($B15/$A15*V26_LCC!D$35) -> 3.1354614 | G15: =ABS($B15/$A15*V26_LCC!E$35) -> 5.5008095 | H15: =ABS($B15/$A15*V26_LCC!F$35) -> 8.2512142 | I15: =ABS($B15/$A15*V26_LCC!G$35) -> 12.548722 | J15: =I15/V26_LCC!$D$114*A15 -> 0.65253353
A16: 1.6 | B16: 0.036155484 | C16: 0.022597178 | D16: 8 | E16: =ABS($B16/$A16*V26_LCC!D$26) -> 1.5075214 | F16: =ABS($B16/$A16*V26_LCC!D$35) -> 3.4371488 | G16: =ABS($B16/$A16*V26_LCC!E$35) -> 6.0300857 | H16: =ABS($B16/$A16*V26_LCC!F$35) -> 9.0451285 | I16: =ABS($B16/$A16*V26_LCC!G$35) -> 13.756133 | J16: =I16/V26_LCC!$D$114*A16 -> 0.71531891 | N16: 0
A17: 1.6 | B17: 0.042204971 | C17: 0.026378107 | D17: 8 | E17: =ABS($B17/$A17*V26_LCC!D$26) -> 1.7597579 | F17: =ABS($B17/$A17*V26_LCC!D$35) -> 4.0122479 | G17: =ABS($B17/$A17*V26_LCC!E$35) -> 7.0390315 | H17: =ABS($B17/$A17*V26_LCC!F$35) -> 10.558547 | I17: =ABS($B17/$A17*V26_LCC!G$35) -> 16.057791 | J17: =I17/V26_LCC!$D$114*A17 -> 0.83500511
A18: 1.86 | B18: 0.033210176 | C18: 0.017854934 | D18: 8 | E18: =ABS($B18/$A18*V26_LCC!D$26) -> 1.1911529 | F18: =ABS($B18/$A18*V26_LCC!D$35) -> 2.7158287 | G18: =ABS($B18/$A18*V26_LCC!E$35) -> 4.7646118 | H18: =ABS($B18/$A18*V26_LCC!F$35) -> 7.1469177 | I18: =ABS($B18/$A18*V26_LCC!G$35) -> 10.869271 | J18: =I18/V26_LCC!$D$114*A18 -> 0.65704741
A19: 1.86 | B19: 0.045445248 | C19: 0.024432929 | D19: 8 | E19: =ABS($B19/$A19*V26_LCC!D$26) -> 1.6299896 | F19: =ABS($B19/$A19*V26_LCC!D$35) -> 3.7163762 | G19: =ABS($B19/$A19*V26_LCC!E$35) -> 6.5199582 | H19: =ABS($B19/$A19*V26_LCC!F$35) -> 9.7799374 | I19: =ABS($B19/$A19*V26_LCC!G$35) -> 14.873655 | J19: =I19/V26_LCC!$D$114*A19 -> 0.89911243
A20: 1.86 | B20: 0.047583151 | C20: 0.025582339 | D20: 1152 | E20: =ABS($B20/$A20*V26_LCC!D$26) -> 1.70667 | F20: =ABS($B20/$A20*V26_LCC!D$35) -> 3.8912076 | G20: =ABS($B20/$A20*V26_LCC!E$35) -> 6.8266799 | H20: =ABS($B20/$A20*V26_LCC!F$35) -> 10.24002 | I20: =ABS($B20/$A20*V26_LCC!G$35) -> 15.573364 | J20: =I20/V26_LCC!$D$114*A20 -> 0.94140983
A21: 1.86 | B21: 0.047763409 | C21: 0.025679252 | D21: 8 | E21: =ABS($B21/$A21*V26_LCC!D$26) -> 1.7131353 | F21: =ABS($B21/$A21*V26_LCC!D$35) -> 3.9059485 | G21: =ABS($B21/$A21*V26_LCC!E$35) -> 6.8525413 | H21: =ABS($B21/$A21*V26_LCC!F$35) -> 10.278812 | I21: =ABS($B21/$A21*V26_LCC!G$35) -> 15.63236 | J21: =I21/V26_LCC!$D$114*A21 -> 0.94497615
A22: 1.86 | B22: 0.04957996 | C22: 0.026655892 | D22: 8 | E22: =ABS($B22/$A22*V26_LCC!D$26) -> 1.7782897 | F22: =ABS($B22/$A22*V26_LCC!D$35) -> 4.0545005 | G22: =ABS($B22/$A22*V26_LCC!E$35) -> 7.1131589 | H22: =ABS($B22/$A22*V26_LCC!F$35) -> 10.669738 | I22: =ABS($B22/$A22*V26_LCC!G$35) -> 16.226894 | J22: =I22/V26_LCC!$D$114*A22 -> 0.98091572
A23: 1.86 | B23: 0.053444377 | C23: 0.028733536 | D23: 8 | E23: =ABS($B23/$A23*V26_LCC!D$26) -> 1.9168952 | F23: =ABS($B23/$A23*V26_LCC!D$35) -> 4.3705211 | G23: =ABS($B23/$A23*V26_LCC!E$35) -> 7.6675808 | H23: =ABS($B23/$A23*V26_LCC!F$35) -> 11.501371 | I23: =ABS($B23/$A23*V26_LCC!G$35) -> 17.491669 | J23: =I23/V26_LCC!$D$114*A23 -> 1.0573714
A24: 1.86 | B24: 0.053887111 | C24: 0.028971565 | D24: 8 | E24: =ABS($B24/$A24*V26_LCC!D$26) -> 1.9327748 | F24: =ABS($B24/$A24*V26_LCC!D$35) -> 4.4067265 | G24: =ABS($B24/$A24*V26_LCC!E$35) -> 7.7310992 | H24: =ABS($B24/$A24*V26_LCC!F$35) -> 11.596649 | I24: =ABS($B24/$A24*V26_LCC!G$35) -> 17.63657 | J24: =I24/V26_LCC!$D$114*A24 -> 1.0661307
A25: 1.86 | B25: 0.060596838 | C25: 0.032578945 | D25: 8 | E25: =ABS($B25/$A25*V26_LCC!D$26) -> 2.1734333 | F25: =ABS($B25/$A25*V26_LCC!D$35) -> 4.9554279 | G25: =ABS($B25/$A25*V26_LCC!E$35) -> 8.6937331 | H25: =ABS($B25/$A25*V26_LCC!F$35) -> 13.0406 | I25: =ABS($B25/$A25*V26_LCC!G$35) -> 19.832579 | J25: =I25/V26_LCC!$D$114*A25 -> 1.1988794
A26: 1.86 | B26: 0.075146184 | C26: 0.040401174 | D26: 8 | E26: =ABS($B26/$A26*V26_LCC!D$26) -> 2.6952762 | F26: =ABS($B26/$A26*V26_LCC!D$35) -> 6.1452298 | G26: =ABS($B26/$A26*V26_LCC!E$35) -> 10.781105 | H26: =ABS($B26/$A26*V26_LCC!F$35) -> 16.171657 | I26: =ABS($B26/$A26*V26_LCC!G$35) -> 24.594395 | J26: =I26/V26_LCC!$D$114*A26 -> 1.4867312
A27: 2.89 | B27: -0.051354231 | C27: -0.01776963 | D27: 8 | E27: =ABS($B27/$A27*V26_LCC!D$26) -> 1.1854621 | F27: =ABS($B27/$A27*V26_LCC!D$35) -> 2.7028536 | G27: =ABS($B27/$A27*V26_LCC!E$35) -> 4.7418485 | H27: =ABS($B27/$A27*V26_LCC!F$35) -> 7.1127727 | I27: =ABS($B27/$A27*V26_LCC!G$35) -> 10.817342 | J27: =I27/V26_LCC!$D$114*A27 -> 1.0160188
A28: 2.89 | B28: -0.048973887 | C28: -0.016945982 | D28: 8 | E28: =ABS($B28/$A28*V26_LCC!D$26) -> 1.1305142 | F28: =ABS($B28/$A28*V26_LCC!D$35) -> 2.5775724 | G28: =ABS($B28/$A28*V26_LCC!E$35) -> 4.5220569 | H28: =ABS($B28/$A28*V26_LCC!F$35) -> 6.7830853 | I28: =ABS($B28/$A28*V26_LCC!G$35) -> 10.315942 | J28: =I28/V26_LCC!$D$114*A28 -> 0.96892487
... A33: 2.89 | B33: -0.03654426 | C33: -0.012645072 | D33: 8 | E33: =ABS($B33/$A33*V26_LCC!D$26) -> 0.84358843 | F33: =ABS($B33/$A33*V26_LCC!D$35) -> 1.9233816 | G33: =ABS($B33/$A33*V26_LCC!E$35) -> 3.3743537 | H33: =ABS($B33/$A33*V26_LCC!F$35) -> 5.0615306 | I33: =ABS($B33/$A33*V26_LCC!G$35) -> 7.6977445 | J33: =I33/V26_LCC!$D$114*A33 -> 0.72301065

Sheet V26_LCC_sextupoles
A1: Length | B1: Integrated strength | C1: Normalized strength [m-3] | D1: Number | E1: Gradient injection [T/m] | F1: Gradient at Z [T/m] | J1: Length min
A2: 0.3 | B2: -0.24228806 | C2: =B2/A2 -> -0.80762688 | D2: 8 | E2: =ABS($B2/$A2*V26_LCC!D$26) -> 53.879066 | F2: =ABS($B2/$A2*V26_LCC!D$35) -> 122.84427 | G2: =ABS($B2/$A2*V26_LCC!E$35) -> 215.51626 | H2: =ABS($B2/$A2*V26_LCC!F$35) -> 323.2744 | I2: =ABS($B2/$A2*V26_LCC!G$35) -> 491.64648 | J2: =I2/V26_LCC!$G$125*A2 -> 0.11127891
A3: 0.3 | B3: -0.20527084 | C3: =B3/A3 -> -0.68423613 | D3: 8 | E3: =ABS($B3/$A3*V26_LCC!D$26) -> 45.647321 | F3: =ABS($B3/$A3*V26_LCC!D$35) -> 104.07589 | G3: =ABS($B3/$A3*V26_LCC!E$35) -> 182.58928 | H3: =ABS($B3/$A3*V26_LCC!F$35) -> 273.88393 | I3: =ABS($B3/$A3*V26_LCC!G$35) -> 416.5318 | J3: =I3/V26_LCC!$G$125*A3 -> 0.094277511 | L3: Total number of magnets | M3: =SUM(D2:D25) -> 1888
A4: 0.3 | B4: -0.16295374 | C4: =B4/A4 -> -0.54317913 | D4: 8 | E4: =ABS($B4/$A4*V26_LCC!D$26) -> 36.237011 | F4: =ABS($B4/$A4*V26_LCC!D$35) -> 82.620385 | G4: =ABS($B4/$A4*V26_LCC!E$35) -> 144.94804 | H4: =ABS($B4/$A4*V26_LCC!F$35) -> 217.42207 | I4: =ABS($B4/$A4*V26_LCC!G$35) -> 330.66273 | J4: =I4/V26_LCC!$G$125*A4 -> 0.074841965 | L4: Total length | M4: =SUMPRODUCT(A2:A25,D2:D25) -> 770.56
A5: 0.3 | B5: -0.014299126 | C5: =B5/A5 -> -0.047663754 | D5: 8 | E5: =ABS($B5/$A5*V26_LCC!D$26) -> 3.1797834 | F5: =ABS($B5/$A5*V26_LCC!D$35) -> 7.2499062 | G5: =ABS($B5/$A5*V26_LCC!E$35) -> 12.719134 | H5: =ABS($B5/$A5*V26_LCC!F$35) -> 19.0787 | I5: =ABS($B5/$A5*V26_LCC!G$35) -> 29.015524 | J5: =I5/V26_LCC!$G$125*A5 -> 0.0065673529 | L5: Total normalized gradient | M5: =SUMPRODUCT((B2:B25)*(D2:D25)*SIGN(B2:B25)) -> 1000.0958
A6: 0.3 | B6: 0.18053271 | C6: =B6/A6 -> 0.60177571 | D6: 8 | E6: =ABS($B6/$A6*V26_LCC!D$26) -> 40.146154 | F6: =ABS($B6/$A6*V26_LCC!D$35) -> 91.533231 | G6: =ABS($B6/$A6*V26_LCC!E$35) -> 160.58462 | H6: =ABS($B6/$A6*V26_LCC!F$35) -> 240.87692 | I6: =ABS($B6/$A6*V26_LCC!G$35) -> 366.33365 | J6: =I6/V26_LCC!$G$125*A6 -> 0.082915698
A7: 0.3 | B7: 0.2327144 | C7: =B7/A7 -> 0.77571465 | D7: 8 | E7: =ABS($B7/$A7*V26_LCC!D$26) -> 51.750111 | F7: =ABS($B7/$A7*V26_LCC!D$35) -> 117.99025 | G7: =ABS($B7/$A7*V26_LCC!E$35) -> 207.00044 | H7: =ABS($B7/$A7*V26_LCC!F$35) -> 310.50067 | I7: =ABS($B7/$A7*V26_LCC!G$35) -> 472.21977 | J7: =I7/V26_LCC!$G$125*A7 -> 0.10688188
A8: 0.3 | B8: 0.37289708 | C8: =B8/A8 -> 1.2429903 | D8: 464 | E8: =ABS($B8/$A8*V26_LCC!D$26) -> 82.923385 | F8: =ABS($B8/$A8*V26_LCC!D$35) -> 189.06532 | G8: =ABS($B8/$A8*V26_LCC!E$35) -> 331.69354 | H8: =ABS($B8/$A8*V26_LCC!F$35) -> 497.54031 | I8: =ABS($B8/$A8*V26_LCC!G$35) -> 756.67589 | J8: =I8/V26_LCC!$G$125*A8 -> 0.17126548
A9: 0.3 | B9: 0.40707198 | C9: =B9/A9 -> 1.3569066 | D9: 448 | E9: =ABS($B9/$A9*V26_LCC!D$26) -> 90.523065 | F9: =ABS($B9/$A9*V26_LCC!D$35) -> 206.39259 | G9: =ABS($B9/$A9*V26_LCC!E$35) -> 362.09226 | H9: =ABS($B9/$A9*V26_LCC!F$35) -> 543.13839 | I9: =ABS($B9/$A9*V26_LCC!G$35) -> 826.02297 | J9: =I9/V26_LCC!$G$125*A9 -> 0.18696145
A10: =0.52 -> 0.52 | B10: -1.5173157 | C10: =B10/A10 -> -2.9179147 | D10: 8 | E10: =ABS($B10/$A10*V26_LCC!D$26) -> 194.66232 | F10: =ABS($B10/$A10*V26_LCC!D$35) -> 443.83008 | G10: =ABS($B10/$A10*V26_LCC!E$35) -> 778.64927 | H10: =ABS($B10/$A10*V26_LCC!F$35) -> 1167.9739 | I10: =ABS($B10/$A10*V26_LCC!G$35) -> 1776.2936 | J10: =I10/V26_LCC!$G$125*A10 -> 0.69687806
A11: 0.52 | B11: -0.73508666 | C11: =B11/A11 -> -1.4136282 | D11: 464 | E11: =ABS($B11/$A11*V26_LCC!D$26) -> 94.307122 | F11: =ABS($B11/$A11*V26_LCC!D$35) -> 215.02024 | G11: =ABS($B11/$A11*V26_LCC!E$35) -> 377.22849 | H11: =ABS($B11/$A11*V26_LCC!F$35) -> 565.84273 | I11: =ABS($B11/$A11*V26_LCC!G$35) -> 860.55248 | J11: =I11/V26_LCC!$G$125*A11 -> 0.33761318 | L11: MIN | M11: Min gradient (injection) T/m | P11: =MIN(E2:E25) -> 3.1797834 | Q11: =MIN(F2:F25) -> 7.2499062 | R11: =MIN(G2:G25) -> 12.719134 | S11: =MIN(H2:H25) -> 19.0787 | T11: =MIN(I2:I25) -> 29.015524
A12: 0.52 | B12: -0.62697235 | C12: =B12/A12 -> -1.2057161 | D12: 448 | E12: =ABS($B12/$A12*V26_LCC!D$26) -> 80.436717 | F12: =ABS($B12/$A12*V26_LCC!D$35) -> 183.39572 | G12: =ABS($B12/$A12*V26_LCC!E$35) -> 321.74687 | H12: =ABS($B12/$A12*V26_LCC!F$35) -> 482.6203 | I12: =ABS($B12/$A12*V26_LCC!G$35) -> 733.98505 | J12: =I12/V26_LCC!$G$125*A12 -> 0.28795806 | L12: MAX | M12: Max gradient (injection) T/m | P12: =MAX(E2:E25) -> 194.66232 | Q12: =MAX(F2:F25) -> 443.83008 | R12: =MAX(G2:G25) -> 778.64927 | S12: =MAX(H2:H25) -> 1167.9739 | T12: =MAX(I2:I25) -> 1776.2936
A13: 0.52 | B13: -0.28706047 | C13: =B13/A13 -> -0.55203937 | D13: 8 | E13: =ABS($B13/$A13*V26_LCC!D$26) -> 36.828103 | F13: =ABS($B13/$A13*V26_LCC!D$35) -> 83.968074 | G13: =ABS($B13/$A13*V26_LCC!E$35) -> 147.31241 | H13: =ABS($B13/$A13*V26_LCC!F$35) -> 220.96862 | I13: =ABS($B13/$A13*V26_LCC!G$35) -> 336.05644 | J13: =I13/V26_LCC!$G$125*A13 -> 0.13184214 | L13: MEAN | M13: Mean gradient (injection) T/m | P13: =SUMPRODUCT($D$2:$D$25,E2:E25)/$M$3 -> 86.082403 | Q13: =SUMPRODUCT($D$2:$D$25,F2:F25)/$M$3 -> 196.26788 | R13: =SUMPRODUCT($D$2:$D$25,G2:G25)/$M$3 -> 344.32961 | S13: =SUMPRODUCT($D$2:$D$25,H2:H25)/$M$3 -> 516.49442 | T13: =SUMPRODUCT($D$2:$D$25,I2:I25)/$M$3 -> 785.50192

Sheet tanx-x
A1: =TAN(B1)-B1 -> 1.2919295e-09 | B1: =ROW()*0.001*PI()/2 -> 0.0015707963
A2: =TAN(B2)-B2 -> 1.0335466e-08 | B2: =ROW()*0.001*PI()/2 -> 0.0031415927
A3: =TAN(B3)-B3 -> 3.4882371e-08 | B3: =ROW()*0.001*PI()/2 -> 0.004712389
A4: =TAN(B4)-B4 -> 8.268471e-08 | B4: =ROW()*0.001*PI()/2 -> 0.0062831853
A5: =TAN(B5)-B5 -> 1.6149501e-07 | B5: =ROW()*0.001*PI()/2 -> 0.0078539816
A6: =TAN(B6)-B6 -> 2.7906641e-07 | B6: =ROW()*0.001*PI()/2 -> 0.009424778
A7: =TAN(B7)-B7 -> 4.431528e-07 | B7: =ROW()*0.001*PI()/2 -> 0.010995574
A8: =TAN(B8)-B8 -> 6.6150902e-07 | B8: =ROW()*0.001*PI()/2 -> 0.012566371
A9: =TAN(B9)-B9 -> 9.4189095e-07 | B9: =ROW()*0.001*PI()/2 -> 0.014137167
A10: =TAN(B10)-B10 -> 1.2920557e-06 | B10: =ROW()*0.001*PI()/2 -> 0.015707963
A11: =TAN(B11)-B11 -> 1.7197618e-06 | B11: =ROW()*0.001*PI()/2 -> 0.01727876
A12: =TAN(B12)-B12 -> 2.2327692e-06 | B12: =ROW()*0.001*PI()/2 -> 0.018849556
... A1000: =TAN(B1000)-B1000 -> 1.6324552e+16 | B1000: =ROW()*0.001*PI()/2 -> 1.5707963
